============================= test session starts ==============================
platform linux -- Python 3.10.11, pytest-7.3.1, pluggy-1.0.0
rootdir: /home/runner/work/git-actions-testing/git-actions-testing
plugins: cov-4.1.0
collected 2 items

test_with_pytest.py ..                                                   [100%]WARNING: Failed to generate report: No data to report.



=============================== warnings summary ===============================
test_with_pytest.py::test1
  /opt/hostedtoolcache/Python/3.10.11/x64/lib/python3.10/site-packages/_pytest/python.py:198: PytestReturnNotNoneWarning: Expected None, but test_with_pytest.py::test1 returned 'Hello World!', which will be an error in a future version of pytest.  Did you mean to use `assert` instead of `return`?
    warnings.warn(

-- Docs: https://docs.pytest.org/en/stable/how-to/capture-warnings.html

---------- coverage: platform linux, python 3.10.11-final-0 ----------

========================= 2 passed, 1 warning in 0.04s =========================
